<robot name="simple_3d_arm">
    <!-- Base Link -->
    <link name="base_link">
        <visual>
            <geometry>
                <cylinder length="0.2" radius="0.1" />
            </geometry>
        </visual>
    </link>
    <!-- Base Rotation Joint -->
    <joint name="base_rotation_joint" type="continuous">
        <parent link="base_link" />
        <child link="arm_base_link" />
        <origin xyz="0 0 0.1" rpy="0 0 0" />
        <axis xyz="0 0 1" />
    </joint>
    <!-- Arm Base Link -->
    <link name="arm_base_link">
        <visual>
            <geometry>
                <cylinder length="0.1" radius="0.05" />
            </geometry>
        </visual>
    </link>
    <!-- Shoulder Joint -->
    <joint name="shoulder_joint" type="revolute">
        <parent link="arm_base_link" />
        <child link="upper_arm_link" />
        <origin xyz="0 0 0.1" rpy="0 0 0" />
        <axis xyz="0 1 0" />
        <limit lower="-1.57" upper="1.57" effort="100" velocity="1.0" />
    </joint>
    <!-- Upper Arm Link -->
    <link name="upper_arm_link">
        <visual>
            <geometry>
                <cylinder length="0.4" radius="0.05" />
            </geometry>
        </visual>
    </link>
    <!-- Elbow Joint -->
    <joint name="elbow_joint" type="revolute">
        <parent link="upper_arm_link" />
        <child link="forearm_link" />
        <origin xyz="0 0 0.4" rpy="0 0 0" />
        <axis xyz="0 1 0" />
        <limit lower="-1.57" upper="1.57" effort="100" velocity="1.0" />
    </joint>
    <!-- Forearm Link -->
    <link name="forearm_link">
        <visual>
            <geometry>
                <cylinder length="0.3" radius="0.04" />
            </geometry>
        </visual>
    </link>
    <transmission name="trans_base_rotation_joint">
        <type>transmission_interface/SimpleTransmission</type>
        <joint name="base_rotation_joint">
            <hardwareInterface>hardware_interface/EffortJointInterface</hardwareInterface>
        </joint>
        <actuator name="base_rotation_joint_motor">
            <hardwareInterface>hardware_interface/EffortJointInterface</hardwareInterface>
            <mechanicalReduction>1</mechanicalReduction>
        </actuator>
    </transmission>
    <transmission name="trans_shoulder_joint">
        <type>transmission_interface/SimpleTransmission</type>
        <joint name="shoulder_joint">
            <hardwareInterface>hardware_interface/EffortJointInterface</hardwareInterface>
        </joint>
        <actuator name="shoulder_joint_motor">
            <hardwareInterface>hardware_interface/EffortJointInterface</hardwareInterface>
            <mechanicalReduction>1</mechanicalReduction>
        </actuator>
    </transmission>
    <transmission name="trans_elbow_joint">
        <type>transmission_interface/SimpleTransmission</type>
        <joint name="elbow_joint">
            <hardwareInterface>hardware_interface/EffortJointInterface</hardwareInterface>
        </joint>
        <actuator name="elbow_joint_motor">
            <hardwareInterface>hardware_interface/EffortJointInterface</hardwareInterface>
            <mechanicalReduction>1</mechanicalReduction>
        </actuator>
    </transmission>
    <gazebo>
        <plugin name="gazebo_ros_control">
            <robotNamespace>/</robotNamespace>
        </plugin>
    </gazebo>
</robot>

